Workbook

Sheet O2C - Produtos acabados
A1: Tipo | B1: Cenário | C1: Processo de Negócio | D1: Tipo OV | E1: Cenário de teste | F1: Usina | G1: Cliente | H1: Material | I1: OV Referência | J1: J1BTax | K1: CFOP | L1: OV no BEC | M1: Val. Fiscal | N1: Remessa | O1: Fatura | P1: NF - DocNum | Q1: Val. Contabil | R1: Val. Tax SAP | S1: Val. Tax One | T1: Observação
A2: Cenário | B2: C_001 | C2: Venda Etanol Hidratado D.E | D2: Y002 | E2: Venda de etanol hidratado dentro do estado
A3: Tarefa | B3: C_001 | C3: Venda Etanol Hidratado D.E | D3: YDEV | E3: Retorno da Venda de etanol hidratado dentro do estado
A4: Tarefa | B4: C_001 | C4: Venda Etanol Hidratado D.E | D4: YRET | E4: Recusa da venda de hidratado dentro do estado
A5: Cenário | B5: C_002 | C5: Venda Etanol Hidratado F.E | D5: Y002 | E5: Venda de etanol hidratado fora do estado
A6: Tarefa | B6: C_002 | C6: Venda Etanol Hidratado F.E | D6: YDEV | E6: Retorno da Venda de etanol hidratado fora do estado
A7: Tarefa | B7: C_002 | C7: Venda Etanol Hidratado F.E | D7: YRET | E7: Recusa da venda de hidratado fora do estado
A8: Cenário | B8: C_003 | C8: Venda Etanol Anidro F.E - Distribuidora | D8: Y002 | E8: Venda de etanol Anidro fora do estado - Distribuidora
A9: Tarefa | B9: C_003 | C9: Venda Etanol Anidro F.E | D9: YDEV | E9: Retorno da Venda de etanol Anidro fora do estado
A10: Tarefa | B10: C_003 | C10: Venda Etanol Anidro F.E | D10: YRET | E10: Recusa da venda de Anidro fora do estado
A11: Cenário | B11: C_004 | C11: Venda Etanol Anidro D.E - Distribuidora | D11: Y002 | E11: Venda de etanol Anidro dentro do estado - Distribuidora
A12: Tarefa | B12: C_004 | C12: Venda Etanol Anidro F.E | D12: YDEV | E12: Retorno da Venda de etanol Anidro fora do estado
A13: Tarefa | B13: C_004 | C13: Venda Etanol Anidro F.E | D13: YRET | E13: Recusa da venda de Anidro fora do estado
... A43: Cenário | B43: C_018 | C43: Venda doméstica Açúcar – CTR | D43: Y073 | E43: Venda de açucar C1C para Femsa_CTR
A44: Tarefa | B44: C_018 | C44: Venda doméstica Açúcar – CTR | E44: Recusa da venda de açucar C1C para Femsa_CTR
A45: Tarefa | B45: C_018 | C45: Venda doméstica Açúcar – CTR | E45: Retorno da venda de açucar C1C para Femsa_CTR
A46: Cenário | B46: C_019 | C46: Venda Etanol Anidro ZFM | D46: Y002 | E46: Venda de etanol Anidro Zona Franca de Manaus
A47: Tarefa | B47: C_019 | C47: Venda Etanol Anidro ZFM | E47: Retorno da Venda de etanol Anidro Zona Franca de Manaus
A48: Tarefa | B48: C_019 | C48: Venda Etanol Anidro ZFM | E48: Recusa da venda de Anidro Zona Franca de Manaus
A49: Cenário | B49: C_020 | C49: VEF - Receita Antecipada | D49: YVFP | E49: VEF - Receita Antecipada
A50: Cenário | B50: C_020 | C50: Remessa VEF - Receita Antecipada | D50: YRFP | E50: Remessa VEF - Receita Antecipada
A51: Tarefa | B51: C_020 | C51: Remessa VEF - Receita Antecipada | D51: YVRC | E51: Recusa da VEF - Etanol (YVRC)
A52: Tarefa | B52: C_020 | C52: Remessa VEF - Receita Antecipada | D52: YVRE | E52: Retorno da VEF - Etanol (YVRE)
A53: Cenário | B53: C_021 | C53: FA - Simples Faturamento | D53: Y003 | E53: FA- Simples Faturamento
A54: Cenário | B54: C_021 | C54: Remessa da FA - Receita Remessa | D54: Y033 | E54: Remessa da FA - Receita Remessa
A55: Tarefa | B55: C_021 | C55: Remessa da FA - Receita Remessa | D55: Y3RC | E55: Recusa da FA - Etanol (Y3RC)
A56: Tarefa | B56: C_021 | C56: Remessa da FA - Receita Remessa | D56: Y3RE | E56: Retorno da FA - Etanol (Y3RE)
A57: Cenário | B57: C_022 | C57: Venda Conta e Ordem | D57: Y032 | E57: Venda Conta e Ordem
A58: Cenário | B58: C_022 | C58: Remessa Conta e Ordem | D58: Y044 | E58: Remessa Conta e Ordem
A59: Tarefa | B59: C_022 | C59: Remessa Conta e Ordem | D59: YSRS | E59: Recusa da Conta e Ordem - Etanol (YSRS)
A60: Tarefa | B60: C_022 | C60: Remessa Conta e Ordem | D60: YDSR | E60: Retorno da Conta e Ordem - Etanol (YDSR)
... A71: Tarefa | B71: C_025 | C71: Venda Bagaço_ YBIO | D71: YRET | E71: Recusa da venda Bagaço
A72: Cenário | B72: C_026 | C72: Venda Energia Dentro Estado Consumo | D72: 0 | E72: Venda Energia Dentro Estado Consumo
A73: Tarefa | B73: C_026 | C73: Venda Energia Dentro Estado Consumo | D73: YRET | E73: Anulação
A74: Cenário | B74: C_027 | C74: Revenda Energia Fora Estado | D74: Y202 | E74: Revenda Energia Fora Estado
A75: Tarefa | B75: C_027 | C75: Revenda Energia Fora Estado | D75: YRET | E75: Anulação
A76: Cenário | B76: C_028 | C76: Venda Energia Fora Estado Consumo | D76: Y202 | E76: Venda Energia Fora Estado Consumo
A77: Tarefa | B77: C_028 | C77: Venda Energia Fora Estado Consumo | D77: YRET | E77: Anulação
A78: Cenário | B78: C_029 | C78: Lastro Energia | D78: Y205 | E78: Lastro Energia
A79: Cenário | B79: C_030 | C79: Venda Energia Biomassa | D79: Y202 | E79: Venda Energia Biomassa
...

Sheet O2C - Diversas
A1: Tipo | B1: Cenário | C1: Processo de Negócio | D1: Tipo OV | E1: Coluna1 | F1: Cenário de teste | G1: Usina | H1: Cliente | I1: Material | J1: OV Referência | K1: J1BTax | L1: CFOP | M1: OV no BEC | N1: Val. Fiscal | O1: Remessa | P1: Fatura | Q1: NF - DocNum | R1: Val. Contabil | S1: Val. Tax SAP | T1: Val. Tax One | U1: Observação
A2: Cenário | B2: C_031 | C2: Venda Melaço | D2: Y007 | E2: =Tabela2[[#This Row],[Processo de Negócio]]&" ("&Tabela2[[#This Row],[Tipo OV]]&")" -> Venda Melaço (Y007) | F2: Venda Melaço
A3: Cenário | B3: C_032 | C3: Venda Agua Vapor | D3: Y002 | E3: =Tabela2[[#This Row],[Processo de Negócio]]&" ("&Tabela2[[#This Row],[Tipo OV]]&")" -> Venda Agua Vapor (Y002) | F3: Venda Agua Vapor
A4: Cenário | B4: C_034 | C4: Transferencia Matriz/Filial | D4: PIMS | E4: =Tabela2[[#This Row],[Processo de Negócio]]&" ("&Tabela2[[#This Row],[Tipo OV]]&")" -> Transferencia Matriz/Filial (PIMS) | F4: Insumos
A5: Cenário | B5: C_035 | C5: Transferencia Matriz/Filial | D5: PIMS | E5: =Tabela2[[#This Row],[Processo de Negócio]]&" ("&Tabela2[[#This Row],[Tipo OV]]&")" -> Transferencia Matriz/Filial (PIMS) | F5: Diesel
A6: Cenário | B6: C_036 | C6: Doação | D6: Y013 | E6: =Tabela2[[#This Row],[Processo de Negócio]]&" ("&Tabela2[[#This Row],[Tipo OV]]&")" -> Doação (Y013) | F6: Doação
A7: Cenário | B7: C_037 | C7: Doação com Movimentação | D7: Y103 | E7: =Tabela2[[#This Row],[Processo de Negócio]]&" ("&Tabela2[[#This Row],[Tipo OV]]&")" -> Doação com Movimentação (Y103) | F7: Doação com Movimentação
A8: Cenário | B8: C_038 | C8: Venda Ativo F.E | D8: Y005 | E8: =Tabela2[[#This Row],[Processo de Negócio]]&" ("&Tabela2[[#This Row],[Tipo OV]]&")" -> Venda Ativo F.E (Y005) | F8: Venda Ativo F.E
A9: Tarefa | B9: C_038 | C9: Venda Ativo F.E | D9: YRET | E9: =Tabela2[[#This Row],[Processo de Negócio]]&" ("&Tabela2[[#This Row],[Tipo OV]]&")" -> Venda Ativo F.E (YRET) | F9: Recusa da venda de ativo F.E
A10: Cenário | B10: C_039 | C10: Venda Sucata - Residuo | D10: Y007 | E10: =Tabela2[[#This Row],[Processo de Negócio]]&" ("&Tabela2[[#This Row],[Tipo OV]]&")" -> Venda Sucata - Residuo (Y007) | F10: Venda Sucata - Residuo
A11: Tarefa | B11: C_039 | C11: Venda Sucata - Residuo | D11: YRE8 | E11: =Tabela2[[#This Row],[Processo de Negócio]]&" ("&Tabela2[[#This Row],[Tipo OV]]&")" -> Venda Sucata - Residuo (YRE8) | F11: Recusa da venda sucata
A12: Tarefa | B12: C_039 | C12: Venda Sucata - Residuo | D12: YDE8 | E12: =Tabela2[[#This Row],[Processo de Negócio]]&" ("&Tabela2[[#This Row],[Tipo OV]]&")" -> Venda Sucata - Residuo (YDE8) | F12: Retorno da venda sucata
A13: Cenário | B13: C_040 | C13: Venda de Serviços | D13: Y017 | E13: =Tabela2[[#This Row],[Processo de Negócio]]&" ("&Tabela2[[#This Row],[Tipo OV]]&")" -> Venda de Serviços (Y017) | F13: Venda de Serviços
... A22: Cenário | B22: C_050 | C22: Inutilização | D22: Y007 | E22: =Tabela2[[#This Row],[Processo de Negócio]]&" ("&Tabela2[[#This Row],[Tipo OV]]&")" -> Inutilização (Y007) | F22: Intercompany (inutilização)

Sheet TNV
A1: ID | B1: Liberado para Testes? | C1: Cenário | D1: Tarefa | E1: Sequência | F1: Descrição | G1: Responsável | H1: BEC (Pedido/Docnum) | I1: Doc Ref BEP | J1: Conferência Elo | K1: Status | L1: Dt Inicial | M1: Tempo Previsto | N1: Dt Conclusão | O1: Observação | P1: ID Tarefa Precedente | Q1: Tarefas por Cenário | R1: Tarefas Concluídas | S1: Cenário Concluído | T1: Elo - Em correção | U1: Keyuser - Aguardando tarefa precedente | V1: Não liberado para testes | W1: Em correção? | X1: Precedentes? | Y1: Bloqueado? | Z1: Dias em pendente Keyuser | AA1: Impedindo processeguir?
A2: =IF(Tabela49[[#This Row],[Cenário]]<>"","TNV-"&MID(Tabela49[[#This Row],[Cenário]],1,4)&"_"&ROW(),"") -> TNV-CT01_2 | C2: CT01 - CTe Vendas | D2: Gerar cenário e pedido | G2: Edson Oliveira | H2: 4705847492 | K2: Keyuser - Concluído | N2: 46001
A3: =IF(Tabela49[[#This Row],[Cenário]]<>"","TNV-"&MID(Tabela49[[#This Row],[Cenário]],1,4)&"_"&ROW(),"") -> TNV-CT01_3 | C3: CT01 - CTe Vendas | D3: Efetuar lançamento (escrituração fiscal) | G3: Edson Oliveira | H3: 46482747 | K3: Keyuser - Concluído | N3: 46001
A4: =IF(Tabela49[[#This Row],[Cenário]]<>"","TNV-"&MID(Tabela49[[#This Row],[Cenário]],1,4)&"_"&ROW(),"") -> TNV-CT01_4 | C4: CT01 - CTe Vendas | D4: Configurar/Parametrizar IVAs | G4: Lívia Martins | K4: Keyuser - Pendente
A5: =IF(Tabela49[[#This Row],[Cenário]]<>"","TNV-"&MID(Tabela49[[#This Row],[Cenário]],1,4)&"_"&ROW(),"") -> TNV-CT01_5 | C5: CT01 - CTe Vendas | D5: Validar ICMS | G5: Giovana Gonçalves | K5: Keyuser - Pendente
A6: =IF(Tabela49[[#This Row],[Cenário]]<>"","TNV-"&MID(Tabela49[[#This Row],[Cenário]],1,4)&"_"&ROW(),"") -> TNV-CT01_6 | C6: CT01 - CTe Vendas | D6: Validar PIS/COFINS/IBS/CBS | G6: Talita Andrade | K6: Keyuser - Pendente
A7: =IF(Tabela49[[#This Row],[Cenário]]<>"","TNV-"&MID(Tabela49[[#This Row],[Cenário]],1,4)&"_"&ROW(),"") -> TNV-CT01_7 | C7: CT01 - CTe Vendas | D7: Validar Retenções | G7: Raquel dos Santos | K7: Keyuser - Pendente
A8: =IF(Tabela49[[#This Row],[Cenário]]<>"","TNV-"&MID(Tabela49[[#This Row],[Cenário]],1,4)&"_"&ROW(),"") -> TNV-CT01_8 | C8: CT01 - CTe Vendas | D8: Validação da contabilização | G8: Naiara Toledo | K8: Keyuser - Pendente
A9: =IF(Tabela49[[#This Row],[Cenário]]<>"","TNV-"&MID(Tabela49[[#This Row],[Cenário]],1,4)&"_"&ROW(),"") -> TNV-CT01_9 | C9: CT01 - CTe Vendas | D9: Validação título financeiro | G9: Elisa Alves | K9: Keyuser - Pendente
A10: =IF(Tabela49[[#This Row],[Cenário]]<>"","TNV-"&MID(Tabela49[[#This Row],[Cenário]],1,4)&"_"&ROW(),"") -> TNV-CT01_10 | C10: CT01 - CTe Vendas | D10: Realizar validação Obrigações Acessórias - TaxOne | G10: Sergio Souza / Giovana Gonçalves | K10: Keyuser - Pendente
A11: =IF(Tabela49[[#This Row],[Cenário]]<>"","TNV-"&MID(Tabela49[[#This Row],[Cenário]],1,4)&"_"&ROW(),"") -> TNV-CT02_11 | C11: CT02 - CTe Compras - Débito Posterior | D11: Gerar cenário e pedido | G11: Edson Oliveira | H11: 4501889037 | K11: Keyuser - Concluído | N11: 46001
A12: =IF(Tabela49[[#This Row],[Cenário]]<>"","TNV-"&MID(Tabela49[[#This Row],[Cenário]],1,4)&"_"&ROW(),"") -> TNV-CT02_12 | C12: CT02 - CTe Compras - Débito Posterior | D12: Efetuar lançamento (escrituração fiscal) | G12: Edson Oliveira | H12: 46482744 | K12: TNV - Em correção | O12: Erro no item 2 - Tributação IBS incorreta
A13: =IF(Tabela49[[#This Row],[Cenário]]<>"","TNV-"&MID(Tabela49[[#This Row],[Cenário]],1,4)&"_"&ROW(),"") -> TNV-CT02_13 | C13: CT02 - CTe Compras - Débito Posterior | D13: Configurar/Parametrizar IVAs | G13: Lívia Martins | K13: Keyuser - Aguardando tarefa precedente
A14: =IF(Tabela49[[#This Row],[Cenário]]<>"","TNV-"&MID(Tabela49[[#This Row],[Cenário]],1,4)&"_"&ROW(),"") -> TNV-CT02_14 | C14: CT02 - CTe Compras - Débito Posterior | D14: Validar ICMS | G14: Giovana Gonçalves | K14: Keyuser - Aguardando tarefa precedente
A15: =IF(Tabela49[[#This Row],[Cenário]]<>"","TNV-"&MID(Tabela49[[#This Row],[Cenário]],1,4)&"_"&ROW(),"") -> TNV-CT02_15 | C15: CT02 - CTe Compras - Débito Posterior | D15: Validar PIS/COFINS/IBS/CBS | G15: Talita Andrade | K15: Keyuser - Aguardando tarefa precedente
A16: =IF(Tabela49[[#This Row],[Cenário]]<>"","TNV-"&MID(Tabela49[[#This Row],[Cenário]],1,4)&"_"&ROW(),"") -> TNV-CT02_16 | C16: CT02 - CTe Compras - Débito Posterior | D16: Validar Retenções | G16: Raquel dos Santos | K16: Keyuser - Aguardando tarefa precedente
A17: =IF(Tabela49[[#This Row],[Cenário]]<>"","TNV-"&MID(Tabela49[[#This Row],[Cenário]],1,4)&"_"&ROW(),"") -> TNV-CT02_17 | C17: CT02 - CTe Compras - Débito Posterior | D17: Validação da contabilização | G17: Naiara Toledo | K17: Keyuser - Aguardando tarefa precedente
A18: =IF(Tabela49[[#This Row],[Cenário]]<>"","TNV-"&MID(Tabela49[[#This Row],[Cenário]],1,4)&"_"&ROW(),"") -> TNV-CT02_18 | C18: CT02 - CTe Compras - Débito Posterior | D18: Validação título financeiro | G18: Elisa Alves | K18: Keyuser - Aguardando tarefa precedente
A19: =IF(Tabela49[[#This Row],[Cenário]]<>"","TNV-"&MID(Tabela49[[#This Row],[Cenário]],1,4)&"_"&ROW(),"") -> TNV-CT02_19 | C19: CT02 - CTe Compras - Débito Posterior | D19: Realizar validação Obrigações Acessórias - TaxOne | G19: Sergio Souza / Giovana Gonçalves | K19: Keyuser - Aguardando tarefa precedente
A20: =IF(Tabela49[[#This Row],[Cenário]]<>"","TNV-"&MID(Tabela49[[#This Row],[Cenário]],1,4)&"_"&ROW(),"") -> TNV-CT05_20 | C20: CT05 - CTe Writer | D20: Gerar cenário e pedido | G20: Edson Oliveira | H20: 46482768 | K20: TNV - Em correção | O20: Ajustes nas linhas de IBS/CBS
A21: =IF(Tabela49[[#This Row],[Cenário]]<>"","TNV-"&MID(Tabela49[[#This Row],[Cenário]],1,4)&"_"&ROW(),"") -> TNV-CT05_21 | C21: CT05 - CTe Writer | D21: Efetuar lançamento (escrituração fiscal) | G21: Edson Oliveira | K21: Keyuser - Aguardando tarefa precedente
A22: =IF(Tabela49[[#This Row],[Cenário]]<>"","TNV-"&MID(Tabela49[[#This Row],[Cenário]],1,4)&"_"&ROW(),"") -> TNV-CT05_22 | C22: CT05 - CTe Writer | D22: Configurar/Parametrizar IVAs | G22: Lívia Martins | K22: Keyuser - Aguardando tarefa precedente
A23: =IF(Tabela49[[#This Row],[Cenário]]<>"","TNV-"&MID(Tabela49[[#This Row],[Cenário]],1,4)&"_"&ROW(),"") -> TNV-CT05_23 | C23: CT05 - CTe Writer | D23: Validar ICMS | G23: Giovana Gonçalves | K23: Keyuser - Aguardando tarefa precedente
A24: =IF(Tabela49[[#This Row],[Cenário]]<>"","TNV-"&MID(Tabela49[[#This Row],[Cenário]],1,4)&"_"&ROW(),"") -> TNV-CT05_24 | C24: CT05 - CTe Writer | D24: Validar PIS/COFINS/IBS/CBS | G24: Talita Andrade | K24: Keyuser - Aguardando tarefa precedente
A25: =IF(Tabela49[[#This Row],[Cenário]]<>"","TNV-"&MID(Tabela49[[#This Row],[Cenário]],1,4)&"_"&ROW(),"") -> TNV-CT05_25 | C25: CT05 - CTe Writer | D25: Validar Retenções | G25: Raquel dos Santos | K25: Keyuser - Aguardando tarefa precedente
A26: =IF(Tabela49[[#This Row],[Cenário]]<>"","TNV-"&MID(Tabela49[[#This Row],[Cenário]],1,4)&"_"&ROW(),"") -> TNV-CT05_26 | C26: CT05 - CTe Writer | D26: Validação da contabilização | G26: Naiara Toledo | K26: Keyuser - Aguardando tarefa precedente
A27: =IF(Tabela49[[#This Row],[Cenário]]<>"","TNV-"&MID(Tabela49[[#This Row],[Cenário]],1,4)&"_"&ROW(),"") -> TNV-CT05_27 | C27: CT05 - CTe Writer | D27: Validação título financeiro | G27: Elisa Alves | K27: Keyuser - Aguardando tarefa precedente
A28: =IF(Tabela49[[#This Row],[Cenário]]<>"","TNV-"&MID(Tabela49[[#This Row],[Cenário]],1,4)&"_"&ROW(),"") -> TNV-CT05_28 | C28: CT05 - CTe Writer | D28: Realizar validação Obrigações Acessórias - TaxOne | G28: Sergio Souza / Giovana Gonçalves | K28: Keyuser - Aguardando tarefa precedente
A29: =IF(Tabela49[[#This Row],[Cenário]]<>"","TNV-"&MID(Tabela49[[#This Row],[Cenário]],1,4)&"_"&ROW(),"") -> TNV-CT09_29 | C29: CT09 - CTe Outros com folha | D29: Gerar cenário e pedido | G29: Edson Oliveira | H29: 4501889077 | K29: Keyuser - Concluído | N29: 46002
A30: =IF(Tabela49[[#This Row],[Cenário]]<>"","TNV-"&MID(Tabela49[[#This Row],[Cenário]],1,4)&"_"&ROW(),"") -> TNV-CT09_30 | C30: CT09 - CTe Outros com folha | D30: Efetuar lançamento (escrituração fiscal) | G30: Edson Oliveira | K30: Não se Aplica
A31: =IF(Tabela49[[#This Row],[Cenário]]<>"","TNV-"&MID(Tabela49[[#This Row],[Cenário]],1,4)&"_"&ROW(),"") -> TNV-CT09_31 | C31: CT09 - CTe Outros com folha | D31: Configurar/Parametrizar IVAs | G31: Lívia Martins | K31: Não se Aplica
A32: =IF(Tabela49[[#This Row],[Cenário]]<>"","TNV-"&MID(Tabela49[[#This Row],[Cenário]],1,4)&"_"&ROW(),"") -> TNV-CT09_32 | C32: CT09 - CTe Outros com folha | D32: Validar ICMS | G32: Giovana Gonçalves | K32: Não se Aplica
A33: =IF(Tabela49[[#This Row],[Cenário]]<>"","TNV-"&MID(Tabela49[[#This Row],[Cenário]],1,4)&"_"&ROW(),"") -> TNV-CT09_33 | C33: CT09 - CTe Outros com folha | D33: Validar PIS/COFINS/IBS/CBS | G33: Talita Andrade | K33: Não se Aplica
A34: =IF(Tabela49[[#This Row],[Cenário]]<>"","TNV-"&MID(Tabela49[[#This Row],[Cenário]],1,4)&"_"&ROW(),"") -> TNV-CT09_34 | C34: CT09 - CTe Outros com folha | D34: Validar Retenções | G34: Raquel dos Santos | K34: Não se Aplica
A35: =IF(Tabela49[[#This Row],[Cenário]]<>"","TNV-"&MID(Tabela49[[#This Row],[Cenário]],1,4)&"_"&ROW(),"") -> TNV-CT09_35 | C35: CT09 - CTe Outros com folha | D35: Validação da contabilização | G35: Naiara Toledo | K35: Não se Aplica
A36: =IF(Tabela49[[#This Row],[Cenário]]<>"","TNV-"&MID(Tabela49[[#This Row],[Cenário]],1,4)&"_"&ROW(),"") -> TNV-CT09_36 | C36: CT09 - CTe Outros com folha | D36: Validação título financeiro | G36: Elisa Alves | K36: Não se Aplica
A37: =IF(Tabela49[[#This Row],[Cenário]]<>"","TNV-"&MID(Tabela49[[#This Row],[Cenário]],1,4)&"_"&ROW(),"") -> TNV-CT09_37 | C37: CT09 - CTe Outros com folha | D37: Realizar validação Obrigações Acessórias - TaxOne | G37: Sergio Souza / Giovana Gonçalves | K37: Não se Aplica
A38: =IF(Tabela49[[#This Row],[Cenário]]<>"","TNV-"&MID(Tabela49[[#This Row],[Cenário]],1,4)&"_"&ROW(),"") -> TNV-CT09_38 | C38: CT09B - CTe Outros sem folha | D38: Gerar cenário e pedido | G38: Edson Oliveira | H38: 4501889041 | K38: Keyuser - Concluído | N38: 46001
A39: =IF(Tabela49[[#This Row],[Cenário]]<>"","TNV-"&MID(Tabela49[[#This Row],[Cenário]],1,4)&"_"&ROW(),"") -> TNV-CT09_39 | C39: CT09B - CTe Outros sem folha | D39: Efetuar lançamento (escrituração fiscal) | G39: Edson Oliveira | H39: 46482745 | K39: Keyuser - Concluído | N39: 46001
A40: =IF(Tabela49[[#This Row],[Cenário]]<>"","TNV-"&MID(Tabela49[[#This Row],[Cenário]],1,4)&"_"&ROW(),"") -> TNV-CT09_40 | C40: CT09B - CTe Outros sem folha | D40: Configurar/Parametrizar IVAs | G40: Lívia Martins | K40: Keyuser - Pendente
...

Sheet Analise-TNV
A1: OUTBOUND
H3: Responsável | I3: Testes QTD | J3: Testes %
H4: Keyuser - Aguardando tarefa precedente | I4: 79 | J4: 0.66949153
H5: Keyuser - Concluído | I5: 15 | J5: 0.12711864
H6: Keyuser - Pendente | I6: 14 | J6: 0.11864407
H7: TNV - Em correção | I7: 10 | J7: 0.084745763
H8: Total Geral | I8: 118 | J8: 1
H13: META DO DIA
H14: Expectativa para conclusão | I14: 46003
H15: Dias uteis até conclusão | I15: =NETWORKDAYS(TODAY(),I14) -> 2
H16: Testes Pendentes | I16: =COUNTIFS(Tabela49[[#All],[Status]],"*")-(COUNTIFS(Tabela49[[#All],[Status]],"Keyuser - Concluído ")+COUNTIFS(Tabela49[[#All],[Status]],"Não se Aplica")) -> 104
H17: Meta para o dia | I17: =I16/I15 -> 52
H20: Status | I20: TNV - Em correção
H22: Responsável | I22: Cenário | J22: Tarefa | K22: Responsável | L22: Contagem de ID
H23: TNV-CT02_12 | I23: CT02 - CTe Compras - Débito Posterior | J23: Efetuar lançamento (escrituração fiscal) | K23: Edson Oliveira | L23: 1
H24: TNV-CT05_20 | I24: CT05 - CTe Writer | J24: Gerar cenário e pedido | K24: Edson Oliveira | L24: 1
H25: TNV-CT10_48 | I25: CT10 - CTe Serviços 67 | J25: Efetuar lançamento (escrituração fiscal) | K25: Edson Oliveira | L25: 1
H26: TNV-MD01_57 | I26: MD01 - Fatura Energia | J26: Efetuar lançamento (escrituração fiscal) | K26: Edson Oliveira | L26: 1
A27: Data | B27: Concluídos | C27: Méta Dia | D27: Saldo Dia | H27: TNV-MD03_66 | I27: MD03 - Nota de Débito | J27: Efetuar lançamento (escrituração fiscal) | K27: Edson Oliveira | L27: 1
A28: 46001 | B28: =COUNTIFS(TNV!N:N,A28,TNV!K:K,"Keyuser - Concluído ") -> 5 | C28: 5 | D28: =B28-C28 -> 0 | H28: TNV-MD04_75 | I28: MD04 - Telecomunicações | J28: Efetuar lançamento (escrituração fiscal) | K28: Edson Oliveira | L28: 1
A29: 46002 | B29: =COUNTIFS(TNV!N:N,A29,TNV!K:K,"Keyuser - Concluído ") -> 10 | C29: 53 | D29: =B29-C29 -> -43 | H29: TNV-MD06_84 | I29: MD06 - Locação | J29: Efetuar lançamento (escrituração fiscal) | K29: Edson Oliveira | L29: 1
H30: TNV-NS01_102 | I30: NS01 - Serviços Diversos | J30: Efetuar lançamento (escrituração fiscal) | K30: Edson Oliveira | L30: 1
H31: TNV-NS02_111 | I31: NS02 - Serviços DPO | J31: Efetuar lançamento (escrituração fiscal) | K31: Edson Oliveira | L31: 1
H32: TNV-NS03_120 | I32: NS03 - Serviços - Folha de Serviço | J32: Efetuar lançamento (escrituração fiscal) | K32: Edson Oliveira | L32: 1
H33: Total Geral | L33: 10
A37: LIBERADOS
A39: Status | B39: Keyuser - Pendente | F39: Status | G39: Keyuser - Aguardando tarefa precedente
A40: Liberado para Testes? | B40: (vazio) | F40: Liberado para Testes? | G40: (Tudo)
A42: Responsável | B42: ID | C42: Cenário | D42: Testes QTD | F42: Responsável | G42: ID | H42: Tarefa | I42: Cenário | J42: Testes QTD
A43: Lívia Martins | B43: TNV-CT01_4 | C43: CT01 - CTe Vendas | D43: 1 | F43: Raquel dos Santos | J43: 11
B44: TNV-CT09_40 | C44: CT09B - CTe Outros sem folha | D44: 1 | F44: Elisa Alves | J44: 11
A45: Elisa Alves | B45: TNV-CT01_9 | C45: CT01 - CTe Vendas | D45: 1 | F45: Naiara Toledo | J45: 11
B46: TNV-CT09_45 | C46: CT09B - CTe Outros sem folha | D46: 1 | F46: Lívia Martins | J46: 11
A47: Naiara Toledo | B47: TNV-CT01_8 | C47: CT01 - CTe Vendas | D47: 1 | F47: Sergio Souza / Giovana Gonçalves | J47: 11
B48: TNV-CT09_44 | C48: CT09B - CTe Outros sem folha | D48: 1 | F48: Giovana Gonçalves | J48: 11
A49: Giovana Gonçalves | B49: TNV-CT01_5 | C49: CT01 - CTe Vendas | D49: 1 | F49: Talita Andrade | J49: 11
B50: TNV-CT09_41 | C50: CT09B - CTe Outros sem folha | D50: 1 | F50: Edson Oliveira | J50: 2
A51: Sergio Souza / Giovana Gonçalves | B51: TNV-CT01_10 | C51: CT01 - CTe Vendas | D51: 1 | F51: Total Geral | J51: 79
B52: TNV-CT09_46 | C52: CT09B - CTe Outros sem folha | D52: 1
A53: Talita Andrade | B53: TNV-CT01_6 | C53: CT01 - CTe Vendas | D53: 1
...

Sheet Outbound
A1: ID | B1: Liberado para Testes? | C1: Cenário | D1: Tarefa | E1: Sequência | F1: Descrição | G1: Responsável | H1: DOC BEC | I1: Doc Ref BEP | J1: Conferência Elo | K1: Status | L1: Dt Inicial | M1: Tempo Previsto | N1: Dt Conclusão | O1: Observação | P1: ID Tarefa Precedente | Q1: Tarefas por Cenário | R1: Tarefas Concluídas | S1: Cenário Concluído | T1: Elo - Em correção | U1: Keyuser - Aguardando tarefa precedente | V1: Não liberado para testes | W1: Em correção? | X1: Precedentes? | Y1: Bloqueado? | Z1: Dias em pendente Keyuser | AA1: Impedindo processeguir?
A2: ="OUT-"&IFERROR(MID(Tabela4[[#This Row],[Cenário]],SEARCH("(",Tabela4[[#This Row],[Cenário]])+1,SEARCH(")",Tabela4[[#This Row],[Cenário]])-SEARCH("(",Tabela4[[#This Row],[Cenário]])-1),"")&"_"&ROW() -> OUT-Y002_2 | B2: Sim | C2: Venda Etanol Hidratado D.E (Y002) | D2: Criar ordem de venda | E2: 1 | F2: Criar ordem de venda | G2: Vania Esteves | H2: 15603600 | I2: BEP: 15572935 | J2: OK | K2: Keyuser - Concluído | L2: 45944 | N2: 45944 | Q2: =COUNTIF(Tabela4[[#All],[Cenário]],Tabela4[[#This Row],[Cenário]]) -> 8 | R2: =COUNTIFS(Tabela4[[#All],[Cenário]],Tabela4[[#This Row],[Cenário]],Tabela4[[#All],[Status]],"Keyuser - Concluído ") -> 7 | S2: =IF(Tabela4[[#This Row],[Tarefas por Cenário]]-Tabela4[[#This Row],[Tarefas Concluídas]]>0,"Não","Sim") -> Não | T2: =COUNTIFS(Tabela4[[#All],[Cenário]],Tabela4[[#This Row],[Cenário]],Tabela4[[#All],[Status]],Tabela4[[#Headers],[Elo - Em correção ]]) -> 0 | U2: =COUNTIFS(Tabela4[[#All],[Cenário]],Tabela4[[#This Row],[Cenário]],Tabela4[[#All],[Status]],Tabela4[[#Headers],[Keyuser - Aguardando tarefa precedente]]) -> 0 | V2: =COUNTIFS(Tabela4[[#All],[Cenário]],Tabela4[[#This Row],[Cenário]],Tabela4[[#All],[Status]],Tabela4[[#Headers],[Não liberado para testes]]) -> 1 | W2: =IF(Tabela4[[#This Row],[Elo - Em correção ]]>0,"Sim","Não") -> Não | X2: =IF(Tabela4[[#This Row],[Keyuser - Aguardando tarefa precedente]]>0,"Sim","Não") -> Não | Y2: =IF(Tabela4[[#This Row],[Não liberado para testes]]>0,"Sim","Não") -> Sim | Z2: =IF(Tabela4[[#This Row],[Status]]="Keyuser - Pendente",NETWORKDAYS(Tabela4[[#This Row],[Dt Inicial]],TODAY()),"") | AA2: =AND(Tabela4[[#This Row],[Status]]="Keyuser - Aguardando tarefa precedente",K1="Keyuser - Concluído ") -> FALSE
A3: ="OUT-"&IFERROR(MID(Tabela4[[#This Row],[Cenário]],SEARCH("(",Tabela4[[#This Row],[Cenário]])+1,SEARCH(")",Tabela4[[#This Row],[Cenário]])-SEARCH("(",Tabela4[[#This Row],[Cenário]])-1),"")&"_"&ROW() -> OUT-Y002_3 | B3: Sim | C3: Venda Etanol Hidratado D.E (Y002) | D3: Realizar validação tributária - Ordem de venda | E3: 2 | F3: Realizar validação tributária - Ordem de venda | G3: Livia Beserra | H3: 15603600 | I3: BEP: 15572935 | J3: OK | K3: Keyuser - Concluído | L3: 45944 | N3: 45944 | Q3: =COUNTIF(Tabela4[[#All],[Cenário]],Tabela4[[#This Row],[Cenário]]) -> 8 | R3: =COUNTIFS(Tabela4[[#All],[Cenário]],Tabela4[[#This Row],[Cenário]],Tabela4[[#All],[Status]],"Keyuser - Concluído ") -> 7 | S3: =IF(Tabela4[[#This Row],[Tarefas por Cenário]]-Tabela4[[#This Row],[Tarefas Concluídas]]>0,"Não","Sim") -> Não | T3: =COUNTIFS(Tabela4[[#All],[Cenário]],Tabela4[[#This Row],[Cenário]],Tabela4[[#All],[Status]],Tabela4[[#Headers],[Elo - Em correção ]]) -> 0 | U3: =COUNTIFS(Tabela4[[#All],[Cenário]],Tabela4[[#This Row],[Cenário]],Tabela4[[#All],[Status]],Tabela4[[#Headers],[Keyuser - Aguardando tarefa precedente]]) -> 0 | V3: =COUNTIFS(Tabela4[[#All],[Cenário]],Tabela4[[#This Row],[Cenário]],Tabela4[[#All],[Status]],Tabela4[[#Headers],[Não liberado para testes]]) -> 1 | W3: =IF(Tabela4[[#This Row],[Elo - Em correção ]]>0,"Sim","Não") -> Não | X3: =IF(Tabela4[[#This Row],[Keyuser - Aguardando tarefa precedente]]>0,"Sim","Não") -> Não | Y3: =IF(Tabela4[[#This Row],[Não liberado para testes]]>0,"Sim","Não") -> Sim | Z3: =IF(Tabela4[[#This Row],[Status]]="Keyuser - Pendente",NETWORKDAYS(Tabela4[[#This Row],[Dt Inicial]],TODAY()),"") | AA3: =AND(Tabela4[[#This Row],[Status]]="Keyuser - Aguardando tarefa precedente",K2="Keyuser - Concluído ") -> FALSE
A4: ="OUT-"&IFERROR(MID(Tabela4[[#This Row],[Cenário]],SEARCH("(",Tabela4[[#This Row],[Cenário]])+1,SEARCH(")",Tabela4[[#This Row],[Cenário]])-SEARCH("(",Tabela4[[#This Row],[Cenário]])-1),"")&"_"&ROW() -> OUT-Y002_4 | B4: Sim | C4: Venda Etanol Hidratado D.E (Y002) | D4: Liberar ordem de venda | E4: 3 | F4: Liberar ordem de venda | G4: Patrick Vianna / Aline Russo | H4: 15603600 | I4: BEP: 15572935 | J4: OK | K4: Keyuser - Concluído | L4: 45945 | N4: 45945 | Q4: =COUNTIF(Tabela4[[#All],[Cenário]],Tabela4[[#This Row],[Cenário]]) -> 8 | R4: =COUNTIFS(Tabela4[[#All],[Cenário]],Tabela4[[#This Row],[Cenário]],Tabela4[[#All],[Status]],"Keyuser - Concluído ") -> 7 | S4: =IF(Tabela4[[#This Row],[Tarefas por Cenário]]-Tabela4[[#This Row],[Tarefas Concluídas]]>0,"Não","Sim") -> Não | T4: =COUNTIFS(Tabela4[[#All],[Cenário]],Tabela4[[#This Row],[Cenário]],Tabela4[[#All],[Status]],Tabela4[[#Headers],[Elo - Em correção ]]) -> 0 | U4: =COUNTIFS(Tabela4[[#All],[Cenário]],Tabela4[[#This Row],[Cenário]],Tabela4[[#All],[Status]],Tabela4[[#Headers],[Keyuser - Aguardando tarefa precedente]]) -> 0 | V4: =COUNTIFS(Tabela4[[#All],[Cenário]],Tabela4[[#This Row],[Cenário]],Tabela4[[#All],[Status]],Tabela4[[#Headers],[Não liberado para testes]]) -> 1 | W4: =IF(Tabela4[[#This Row],[Elo - Em correção ]]>0,"Sim","Não") -> Não | X4: =IF(Tabela4[[#This Row],[Keyuser - Aguardando tarefa precedente]]>0,"Sim","Não") -> Não | Y4: =IF(Tabela4[[#This Row],[Não liberado para testes]]>0,"Sim","Não") -> Sim | Z4: =IF(Tabela4[[#This Row],[Status]]="Keyuser - Pendente",NETWORKDAYS(Tabela4[[#This Row],[Dt Inicial]],TODAY()),"") | AA4: =AND(Tabela4[[#This Row],[Status]]="Keyuser - Aguardando tarefa precedente",K3="Keyuser - Concluído ") -> FALSE
A5: ="OUT-"&IFERROR(MID(Tabela4[[#This Row],[Cenário]],SEARCH("(",Tabela4[[#This Row],[Cenário]])+1,SEARCH(")",Tabela4[[#This Row],[Cenário]])-SEARCH("(",Tabela4[[#This Row],[Cenário]])-1),"")&"_"&ROW() -> OUT-Y002_5 | B5: Sim | C5: Venda Etanol Hidratado D.E (Y002) | D5: Realizar faturamento | E5: 4 | F5: Realizar faturamento | G5: Francisco Netto | H5: DocNum - 46482170 | K5: Keyuser - Concluído | L5: 45945 | N5: 45945 | Q5: =COUNTIF(Tabela4[[#All],[Cenário]],Tabela4[[#This Row],[Cenário]]) -> 8 | R5: =COUNTIFS(Tabela4[[#All],[Cenário]],Tabela4[[#This Row],[Cenário]],Tabela4[[#All],[Status]],"Keyuser - Concluído ") -> 7 | S5: =IF(Tabela4[[#This Row],[Tarefas por Cenário]]-Tabela4[[#This Row],[Tarefas Concluídas]]>0,"Não","Sim") -> Não | T5: =COUNTIFS(Tabela4[[#All],[Cenário]],Tabela4[[#This Row],[Cenário]],Tabela4[[#All],[Status]],Tabela4[[#Headers],[Elo - Em correção ]]) -> 0 | U5: =COUNTIFS(Tabela4[[#All],[Cenário]],Tabela4[[#This Row],[Cenário]],Tabela4[[#All],[Status]],Tabela4[[#Headers],[Keyuser - Aguardando tarefa precedente]]) -> 0 | V5: =COUNTIFS(Tabela4[[#All],[Cenário]],Tabela4[[#This Row],[Cenário]],Tabela4[[#All],[Status]],Tabela4[[#Headers],[Não liberado para testes]]) -> 1 | W5: =IF(Tabela4[[#This Row],[Elo - Em correção ]]>0,"Sim","Não") -> Não | X5: =IF(Tabela4[[#This Row],[Keyuser - Aguardando tarefa precedente]]>0,"Sim","Não") -> Não | Y5: =IF(Tabela4[[#This Row],[Não liberado para testes]]>0,"Sim","Não") -> Sim | Z5: =IF(Tabela4[[#This Row],[Status]]="Keyuser - Pendente",NETWORKDAYS(Tabela4[[#This Row],[Dt Inicial]],TODAY()),"") | AA5: =AND(Tabela4[[#This Row],[Status]]="Keyuser - Aguardando tarefa precedente",K4="Keyuser - Concluído ") -> FALSE
A6: ="OUT-"&IFERROR(MID(Tabela4[[#This Row],[Cenário]],SEARCH("(",Tabela4[[#This Row],[Cenário]])+1,SEARCH(")",Tabela4[[#This Row],[Cenário]])-SEARCH("(",Tabela4[[#This Row],[Cenário]])-1),"")&"_"&ROW() -> OUT-Y002_6 | B6: Sim | C6: Venda Etanol Hidratado D.E (Y002) | D6: Realizar validação tributária - SAP, XML e DANFE | E6: 5 | F6: Realizar validação tributária - SAP (xml e DANFE) | G6: Sergio Souza / Giovana Gonçalves | H6: DocNum - 46482170 | K6: Keyuser - Concluído | L6: 45945 | N6: 45945 | Q6: =COUNTIF(Tabela4[[#All],[Cenário]],Tabela4[[#This Row],[Cenário]]) -> 8 | R6: =COUNTIFS(Tabela4[[#All],[Cenário]],Tabela4[[#This Row],[Cenário]],Tabela4[[#All],[Status]],"Keyuser - Concluído ") -> 7 | S6: =IF(Tabela4[[#This Row],[Tarefas por Cenário]]-Tabela4[[#This Row],[Tarefas Concluídas]]>0,"Não","Sim") -> Não | T6: =COUNTIFS(Tabela4[[#All],[Cenário]],Tabela4[[#This Row],[Cenário]],Tabela4[[#All],[Status]],Tabela4[[#Headers],[Elo - Em correção ]]) -> 0 | U6: =COUNTIFS(Tabela4[[#All],[Cenário]],Tabela4[[#This Row],[Cenário]],Tabela4[[#All],[Status]],Tabela4[[#Headers],[Keyuser - Aguardando tarefa precedente]]) -> 0 | V6: =COUNTIFS(Tabela4[[#All],[Cenário]],Tabela4[[#This Row],[Cenário]],Tabela4[[#All],[Status]],Tabela4[[#Headers],[Não liberado para testes]]) -> 1 | W6: =IF(Tabela4[[#This Row],[Elo - Em correção ]]>0,"Sim","Não") -> Não | X6: =IF(Tabela4[[#This Row],[Keyuser - Aguardando tarefa precedente]]>0,"Sim","Não") -> Não | Y6: =IF(Tabela4[[#This Row],[Não liberado para testes]]>0,"Sim","Não") -> Sim | Z6: =IF(Tabela4[[#This Row],[Status]]="Keyuser - Pendente",NETWORKDAYS(Tabela4[[#This Row],[Dt Inicial]],TODAY()),"") | AA6: =AND(Tabela4[[#This Row],[Status]]="Keyuser - Aguardando tarefa precedente",K5="Keyuser - Concluído ") -> FALSE
A7: ="OUT-"&IFERROR(MID(Tabela4[[#This Row],[Cenário]],SEARCH("(",Tabela4[[#This Row],[Cenário]])+1,SEARCH(")",Tabela4[[#This Row],[Cenário]])-SEARCH("(",Tabela4[[#This Row],[Cenário]])-1),"")&"_"&ROW() -> OUT-Y002_7 | B7: Sim | C7: Venda Etanol Hidratado D.E (Y002) | D7: Realizar validação contábil | E7: 6 | F7: Realizar validação contábil | G7: Naiara Toledo | H7: DocNum - 46482170 | K7: Keyuser - Concluído | L7: 45945 | N7: 45945 | Q7: =COUNTIF(Tabela4[[#All],[Cenário]],Tabela4[[#This Row],[Cenário]]) -> 8 | R7: =COUNTIFS(Tabela4[[#All],[Cenário]],Tabela4[[#This Row],[Cenário]],Tabela4[[#All],[Status]],"Keyuser - Concluído ") -> 7 | S7: =IF(Tabela4[[#This Row],[Tarefas por Cenário]]-Tabela4[[#This Row],[Tarefas Concluídas]]>0,"Não","Sim") -> Não | T7: =COUNTIFS(Tabela4[[#All],[Cenário]],Tabela4[[#This Row],[Cenário]],Tabela4[[#All],[Status]],Tabela4[[#Headers],[Elo - Em correção ]]) -> 0 | U7: =COUNTIFS(Tabela4[[#All],[Cenário]],Tabela4[[#This Row],[Cenário]],Tabela4[[#All],[Status]],Tabela4[[#Headers],[Keyuser - Aguardando tarefa precedente]]) -> 0 | V7: =COUNTIFS(Tabela4[[#All],[Cenário]],Tabela4[[#This Row],[Cenário]],Tabela4[[#All],[Status]],Tabela4[[#Headers],[Não liberado para testes]]) -> 1 | W7: =IF(Tabela4[[#This Row],[Elo - Em correção ]]>0,"Sim","Não") -> Não | X7: =IF(Tabela4[[#This Row],[Keyuser - Aguardando tarefa precedente]]>0,"Sim","Não") -> Não | Y7: =IF(Tabela4[[#This Row],[Não liberado para testes]]>0,"Sim","Não") -> Sim | Z7: =IF(Tabela4[[#This Row],[Status]]="Keyuser - Pendente",NETWORKDAYS(Tabela4[[#This Row],[Dt Inicial]],TODAY()),"") | AA7: =AND(Tabela4[[#This Row],[Status]]="Keyuser - Aguardando tarefa precedente",K6="Keyuser - Concluído ") -> FALSE
A8: ="OUT-"&IFERROR(MID(Tabela4[[#This Row],[Cenário]],SEARCH("(",Tabela4[[#This Row],[Cenário]])+1,SEARCH(")",Tabela4[[#This Row],[Cenário]])-SEARCH("(",Tabela4[[#This Row],[Cenário]])-1),"")&"_"&ROW() -> OUT-Y002_8 | B8: Não | C8: Venda Etanol Hidratado D.E (Y002) | D8: Realizar validação Obrigações Acessórias - TaxOne | E8: 7 | F8: Realizar validação Obrigações Acessórias - TaxOne | G8: Sergio Souza / Giovana Gonçalves | K8: Não liberado para testes | Q8: =COUNTIF(Tabela4[[#All],[Cenário]],Tabela4[[#This Row],[Cenário]]) -> 8 | R8: =COUNTIFS(Tabela4[[#All],[Cenário]],Tabela4[[#This Row],[Cenário]],Tabela4[[#All],[Status]],"Keyuser - Concluído ") -> 7 | S8: =IF(Tabela4[[#This Row],[Tarefas por Cenário]]-Tabela4[[#This Row],[Tarefas Concluídas]]>0,"Não","Sim") -> Não | T8: =COUNTIFS(Tabela4[[#All],[Cenário]],Tabela4[[#This Row],[Cenário]],Tabela4[[#All],[Status]],Tabela4[[#Headers],[Elo - Em correção ]]) -> 0 | U8: =COUNTIFS(Tabela4[[#All],[Cenário]],Tabela4[[#This Row],[Cenário]],Tabela4[[#All],[Status]],Tabela4[[#Headers],[Keyuser - Aguardando tarefa precedente]]) -> 0 | V8: =COUNTIFS(Tabela4[[#All],[Cenário]],Tabela4[[#This Row],[Cenário]],Tabela4[[#All],[Status]],Tabela4[[#Headers],[Não liberado para testes]]) -> 1 | W8: =IF(Tabela4[[#This Row],[Elo - Em correção ]]>0,"Sim","Não") -> Não | X8: =IF(Tabela4[[#This Row],[Keyuser - Aguardando tarefa precedente]]>0,"Sim","Não") -> Não | Y8: =IF(Tabela4[[#This Row],[Não liberado para testes]]>0,"Sim","Não") -> Sim | Z8: =IF(Tabela4[[#This Row],[Status]]="Keyuser - Pendente",NETWORKDAYS(Tabela4[[#This Row],[Dt Inicial]],TODAY()),"") | AA8: =AND(Tabela4[[#This Row],[Status]]="Keyuser - Aguardando tarefa precedente",K7="Keyuser - Concluído ") -> FALSE
A9: ="OUT-"&IFERROR(MID(Tabela4[[#This Row],[Cenário]],SEARCH("(",Tabela4[[#This Row],[Cenário]])+1,SEARCH(")",Tabela4[[#This Row],[Cenário]])-SEARCH("(",Tabela4[[#This Row],[Cenário]])-1),"")&"_"&ROW() -> OUT-Y002_9 | B9: Sim | C9: Venda Etanol Hidratado D.E (Y002) | D9: Realizar validação Títulos Financeiros | E9: 8 | F9: Realizar validação Títulos Financeiros | G9: Patrick Vianna / Aline Russo | H9: 15603600 | I9: BEP: 15572935 | J9: OK | K9: Keyuser - Concluído | L9: 45950 | N9: 45950 | Q9: =COUNTIF(Tabela4[[#All],[Cenário]],Tabela4[[#This Row],[Cenário]]) -> 8 | R9: =COUNTIFS(Tabela4[[#All],[Cenário]],Tabela4[[#This Row],[Cenário]],Tabela4[[#All],[Status]],"Keyuser - Concluído ") -> 7 | S9: =IF(Tabela4[[#This Row],[Tarefas por Cenário]]-Tabela4[[#This Row],[Tarefas Concluídas]]>0,"Não","Sim") -> Não | T9: =COUNTIFS(Tabela4[[#All],[Cenário]],Tabela4[[#This Row],[Cenário]],Tabela4[[#All],[Status]],Tabela4[[#Headers],[Elo - Em correção ]]) -> 0 | U9: =COUNTIFS(Tabela4[[#All],[Cenário]],Tabela4[[#This Row],[Cenário]],Tabela4[[#All],[Status]],Tabela4[[#Headers],[Keyuser - Aguardando tarefa precedente]]) -> 0 | V9: =COUNTIFS(Tabela4[[#All],[Cenário]],Tabela4[[#This Row],[Cenário]],Tabela4[[#All],[Status]],Tabela4[[#Headers],[Não liberado para testes]]) -> 1 | W9: =IF(Tabela4[[#This Row],[Elo - Em correção ]]>0,"Sim","Não") -> Não | X9: =IF(Tabela4[[#This Row],[Keyuser - Aguardando tarefa precedente]]>0,"Sim","Não") -> Não | Y9: =IF(Tabela4[[#This Row],[Não liberado para testes]]>0,"Sim","Não") -> Sim | Z9: =IF(Tabela4[[#This Row],[Status]]="Keyuser - Pendente",NETWORKDAYS(Tabela4[[#This Row],[Dt Inicial]],TODAY()),"") | AA9: =AND(Tabela4[[#This Row],[Status]]="Keyuser - Aguardando tarefa precedente",K8="Keyuser - Concluído ") -> FALSE
A10: ="OUT-"&IFERROR(MID(Tabela4[[#This Row],[Cenário]],SEARCH("(",Tabela4[[#This Row],[Cenário]])+1,SEARCH(")",Tabela4[[#This Row],[Cenário]])-SEARCH("(",Tabela4[[#This Row],[Cenário]])-1),"")&"_"&ROW() -> OUT-YDEV_10 | B10: Sim | C10: Venda Etanol Hidratado D.E (YDEV) | D10: Criar ordem de venda | E10: 1 | F10: Criar ordem de venda | G10: Marcos Nunes | H10: 60668325 | K10: Keyuser - Concluído | L10: 45958 | N10: 45958 | Q10: =COUNTIF(Tabela4[[#All],[Cenário]],Tabela4[[#This Row],[Cenário]]) -> 6 | R10: =COUNTIFS(Tabela4[[#All],[Cenário]],Tabela4[[#This Row],[Cenário]],Tabela4[[#All],[Status]],"Keyuser - Concluído ") -> 5 | S10: =IF(Tabela4[[#This Row],[Tarefas por Cenário]]-Tabela4[[#This Row],[Tarefas Concluídas]]>0,"Não","Sim") -> Não | T10: =COUNTIFS(Tabela4[[#All],[Cenário]],Tabela4[[#This Row],[Cenário]],Tabela4[[#All],[Status]],Tabela4[[#Headers],[Elo - Em correção ]]) -> 0 | U10: =COUNTIFS(Tabela4[[#All],[Cenário]],Tabela4[[#This Row],[Cenário]],Tabela4[[#All],[Status]],Tabela4[[#Headers],[Keyuser - Aguardando tarefa precedente]]) -> 0 | V10: =COUNTIFS(Tabela4[[#All],[Cenário]],Tabela4[[#This Row],[Cenário]],Tabela4[[#All],[Status]],Tabela4[[#Headers],[Não liberado para testes]]) -> 1 | W10: =IF(Tabela4[[#This Row],[Elo - Em correção ]]>0,"Sim","Não") -> Não | X10: =IF(Tabela4[[#This Row],[Keyuser - Aguardando tarefa precedente]]>0,"Sim","Não") -> Não | Y10: =IF(Tabela4[[#This Row],[Não liberado para testes]]>0,"Sim","Não") -> Sim | Z10: =IF(Tabela4[[#This Row],[Status]]="Keyuser - Pendente",NETWORKDAYS(Tabela4[[#This Row],[Dt Inicial]],TODAY()),"") | AA10: =AND(Tabela4[[#This Row],[Status]]="Keyuser - Aguardando tarefa precedente",K9="Keyuser - Concluído ") -> FALSE
A11: ="OUT-"&IFERROR(MID(Tabela4[[#This Row],[Cenário]],SEARCH("(",Tabela4[[#This Row],[Cenário]])+1,SEARCH(")",Tabela4[[#This Row],[Cenário]])-SEARCH("(",Tabela4[[#This Row],[Cenário]])-1),"")&"_"&ROW() -> OUT-YDEV_11 | B11: Sim | C11: Venda Etanol Hidratado D.E (YDEV) | D11: Realizar validação tributária - Ordem de venda | E11: 2 | F11: Realizar validação tributária - Ordem de venda | G11: Livia Beserra | H11: 60668325 | K11: Keyuser - Concluído | L11: 45958 | N11: 45958 | Q11: =COUNTIF(Tabela4[[#All],[Cenário]],Tabela4[[#This Row],[Cenário]]) -> 6 | R11: =COUNTIFS(Tabela4[[#All],[Cenário]],Tabela4[[#This Row],[Cenário]],Tabela4[[#All],[Status]],"Keyuser - Concluído ") -> 5 | S11: =IF(Tabela4[[#This Row],[Tarefas por Cenário]]-Tabela4[[#This Row],[Tarefas Concluídas]]>0,"Não","Sim") -> Não | T11: =COUNTIFS(Tabela4[[#All],[Cenário]],Tabela4[[#This Row],[Cenário]],Tabela4[[#All],[Status]],Tabela4[[#Headers],[Elo - Em correção ]]) -> 0 | U11: =COUNTIFS(Tabela4[[#All],[Cenário]],Tabela4[[#This Row],[Cenário]],Tabela4[[#All],[Status]],Tabela4[[#Headers],[Keyuser - Aguardando tarefa precedente]]) -> 0 | V11: =COUNTIFS(Tabela4[[#All],[Cenário]],Tabela4[[#This Row],[Cenário]],Tabela4[[#All],[Status]],Tabela4[[#Headers],[Não liberado para testes]]) -> 1 | W11: =IF(Tabela4[[#This Row],[Elo - Em correção ]]>0,"Sim","Não") -> Não | X11: =IF(Tabela4[[#This Row],[Keyuser - Aguardando tarefa precedente]]>0,"Sim","Não") -> Não | Y11: =IF(Tabela4[[#This Row],[Não liberado para testes]]>0,"Sim","Não") -> Sim | Z11: =IF(Tabela4[[#This Row],[Status]]="Keyuser - Pendente",NETWORKDAYS(Tabela4[[#This Row],[Dt Inicial]],TODAY()),"") | AA11: =AND(Tabela4[[#This Row],[Status]]="Keyuser - Aguardando tarefa precedente",K10="Keyuser - Concluído ") -> FALSE
A12: ="OUT-"&IFERROR(MID(Tabela4[[#This Row],[Cenário]],SEARCH("(",Tabela4[[#This Row],[Cenário]])+1,SEARCH(")",Tabela4[[#This Row],[Cenário]])-SEARCH("(",Tabela4[[#This Row],[Cenário]])-1),"")&"_"&ROW() -> OUT-YDEV_12 | B12: Sim | C12: Venda Etanol Hidratado D.E (YDEV) | D12: Realizar faturamento | E12: 3 | F12: Realizar faturamento | G12: Marcos Nunes | H12: Doc Num - 46482274 | K12: Keyuser - Concluído | L12: 45958 | N12: 45958 | O12: Nota nr 149727 | Q12: =COUNTIF(Tabela4[[#All],[Cenário]],Tabela4[[#This Row],[Cenário]]) -> 6 | R12: =COUNTIFS(Tabela4[[#All],[Cenário]],Tabela4[[#This Row],[Cenário]],Tabela4[[#All],[Status]],"Keyuser - Concluído ") -> 5 | S12: =IF(Tabela4[[#This Row],[Tarefas por Cenário]]-Tabela4[[#This Row],[Tarefas Concluídas]]>0,"Não","Sim") -> Não | T12: =COUNTIFS(Tabela4[[#All],[Cenário]],Tabela4[[#This Row],[Cenário]],Tabela4[[#All],[Status]],Tabela4[[#Headers],[Elo - Em correção ]]) -> 0 | U12: =COUNTIFS(Tabela4[[#All],[Cenário]],Tabela4[[#This Row],[Cenário]],Tabela4[[#All],[Status]],Tabela4[[#Headers],[Keyuser - Aguardando tarefa precedente]]) -> 0 | V12: =COUNTIFS(Tabela4[[#All],[Cenário]],Tabela4[[#This Row],[Cenário]],Tabela4[[#All],[Status]],Tabela4[[#Headers],[Não liberado para testes]]) -> 1 | W12: =IF(Tabela4[[#This Row],[Elo - Em correção ]]>0,"Sim","Não") -> Não | X12: =IF(Tabela4[[#This Row],[Keyuser - Aguardando tarefa precedente]]>0,"Sim","Não") -> Não | Y12: =IF(Tabela4[[#This Row],[Não liberado para testes]]>0,"Sim","Não") -> Sim | Z12: =IF(Tabela4[[#This Row],[Status]]="Keyuser - Pendente",NETWORKDAYS(Tabela4[[#This Row],[Dt Inicial]],TODAY()),"") | AA12: =AND(Tabela4[[#This Row],[Status]]="Keyuser - Aguardando tarefa precedente",K11="Keyuser - Concluído ") -> FALSE
A13: ="OUT-"&IFERROR(MID(Tabela4[[#This Row],[Cenário]],SEARCH("(",Tabela4[[#This Row],[Cenário]])+1,SEARCH(")",Tabela4[[#This Row],[Cenário]])-SEARCH("(",Tabela4[[#This Row],[Cenário]])-1),"")&"_"&ROW() -> OUT-YDEV_13 | B13: Sim | C13: Venda Etanol Hidratado D.E (YDEV) | D13: Realizar validação tributária - SAP, XML e DANFE | E13: 4 | F13: Realizar validação tributária - SAP (xml e DANFE) | G13: Sergio Souza / Giovana Gonçalves | H13: Doc Num - 46482274 | K13: Keyuser - Concluído | L13: 45959 | N13: 45959 | Q13: =COUNTIF(Tabela4[[#All],[Cenário]],Tabela4[[#This Row],[Cenário]]) -> 6 | R13: =COUNTIFS(Tabela4[[#All],[Cenário]],Tabela4[[#This Row],[Cenário]],Tabela4[[#All],[Status]],"Keyuser - Concluído ") -> 5 | S13: =IF(Tabela4[[#This Row],[Tarefas por Cenário]]-Tabela4[[#This Row],[Tarefas Concluídas]]>0,"Não","Sim") -> Não | T13: =COUNTIFS(Tabela4[[#All],[Cenário]],Tabela4[[#This Row],[Cenário]],Tabela4[[#All],[Status]],Tabela4[[#Headers],[Elo - Em correção ]]) -> 0 | U13: =COUNTIFS(Tabela4[[#All],[Cenário]],Tabela4[[#This Row],[Cenário]],Tabela4[[#All],[Status]],Tabela4[[#Headers],[Keyuser - Aguardando tarefa precedente]]) -> 0 | V13: =COUNTIFS(Tabela4[[#All],[Cenário]],Tabela4[[#This Row],[Cenário]],Tabela4[[#All],[Status]],Tabela4[[#Headers],[Não liberado para testes]]) -> 1 | W13: =IF(Tabela4[[#This Row],[Elo - Em correção ]]>0,"Sim","Não") -> Não | X13: =IF(Tabela4[[#This Row],[Keyuser - Aguardando tarefa precedente]]>0,"Sim","Não") -> Não | Y13: =IF(Tabela4[[#This Row],[Não liberado para testes]]>0,"Sim","Não") -> Sim | Z13: =IF(Tabela4[[#This Row],[Status]]="Keyuser - Pendente",NETWORKDAYS(Tabela4[[#This Row],[Dt Inicial]],TODAY()),"") | AA13: =AND(Tabela4[[#This Row],[Status]]="Keyuser - Aguardando tarefa precedente",K12="Keyuser - Concluído ") -> FALSE
A14: ="OUT-"&IFERROR(MID(Tabela4[[#This Row],[Cenário]],SEARCH("(",Tabela4[[#This Row],[Cenário]])+1,SEARCH(")",Tabela4[[#This Row],[Cenário]])-SEARCH("(",Tabela4[[#This Row],[Cenário]])-1),"")&"_"&ROW() -> OUT-YDEV_14 | B14: Sim | C14: Venda Etanol Hidratado D.E (YDEV) | D14: Realizar validação contábil | E14: 5 | F14: Realizar validação contábil | G14: Naiara Toledo | H14: Doc Num - 46482274 | K14: Keyuser - Concluído | L14: 45960 | N14: 45960 | Q14: =COUNTIF(Tabela4[[#All],[Cenário]],Tabela4[[#This Row],[Cenário]]) -> 6 | R14: =COUNTIFS(Tabela4[[#All],[Cenário]],Tabela4[[#This Row],[Cenário]],Tabela4[[#All],[Status]],"Keyuser - Concluído ") -> 5 | S14: =IF(Tabela4[[#This Row],[Tarefas por Cenário]]-Tabela4[[#This Row],[Tarefas Concluídas]]>0,"Não","Sim") -> Não | T14: =COUNTIFS(Tabela4[[#All],[Cenário]],Tabela4[[#This Row],[Cenário]],Tabela4[[#All],[Status]],Tabela4[[#Headers],[Elo - Em correção ]]) -> 0 | U14: =COUNTIFS(Tabela4[[#All],[Cenário]],Tabela4[[#This Row],[Cenário]],Tabela4[[#All],[Status]],Tabela4[[#Headers],[Keyuser - Aguardando tarefa precedente]]) -> 0 | V14: =COUNTIFS(Tabela4[[#All],[Cenário]],Tabela4[[#This Row],[Cenário]],Tabela4[[#All],[Status]],Tabela4[[#Headers],[Não liberado para testes]]) -> 1 | W14: =IF(Tabela4[[#This Row],[Elo - Em correção ]]>0,"Sim","Não") -> Não | X14: =IF(Tabela4[[#This Row],[Keyuser - Aguardando tarefa precedente]]>0,"Sim","Não") -> Não | Y14: =IF(Tabela4[[#This Row],[Não liberado para testes]]>0,"Sim","Não") -> Sim | Z14: =IF(Tabela4[[#This Row],[Status]]="Keyuser - Pendente",NETWORKDAYS(Tabela4[[#This Row],[Dt Inicial]],TODAY()),"") | AA14: =AND(Tabela4[[#This Row],[Status]]="Keyuser - Aguardando tarefa precedente",K13="Keyuser - Concluído ") -> FALSE
A15: ="OUT-"&IFERROR(MID(Tabela4[[#This Row],[Cenário]],SEARCH("(",Tabela4[[#This Row],[Cenário]])+1,SEARCH(")",Tabela4[[#This Row],[Cenário]])-SEARCH("(",Tabela4[[#This Row],[Cenário]])-1),"")&"_"&ROW() -> OUT-YDEV_15 | B15: Não | C15: Venda Etanol Hidratado D.E (YDEV) | D15: Realizar validação Obrigações Acessórias - TaxOne | E15: 6 | F15: Realizar validação Obrigações Acessórias - TaxOne | G15: Sergio Souza / Giovana Gonçalves | K15: Não liberado para testes | Q15: =COUNTIF(Tabela4[[#All],[Cenário]],Tabela4[[#This Row],[Cenário]]) -> 6 | R15: =COUNTIFS(Tabela4[[#All],[Cenário]],Tabela4[[#This Row],[Cenário]],Tabela4[[#All],[Status]],"Keyuser - Concluído ") -> 5 | S15: =IF(Tabela4[[#This Row],[Tarefas por Cenário]]-Tabela4[[#This Row],[Tarefas Concluídas]]>0,"Não","Sim") -> Não | T15: =COUNTIFS(Tabela4[[#All],[Cenário]],Tabela4[[#This Row],[Cenário]],Tabela4[[#All],[Status]],Tabela4[[#Headers],[Elo - Em correção ]]) -> 0 | U15: =COUNTIFS(Tabela4[[#All],[Cenário]],Tabela4[[#This Row],[Cenário]],Tabela4[[#All],[Status]],Tabela4[[#Headers],[Keyuser - Aguardando tarefa precedente]]) -> 0 | V15: =COUNTIFS(Tabela4[[#All],[Cenário]],Tabela4[[#This Row],[Cenário]],Tabela4[[#All],[Status]],Tabela4[[#Headers],[Não liberado para testes]]) -> 1 | W15: =IF(Tabela4[[#This Row],[Elo - Em correção ]]>0,"Sim","Não") -> Não | X15: =IF(Tabela4[[#This Row],[Keyuser - Aguardando tarefa precedente]]>0,"Sim","Não") -> Não | Y15: =IF(Tabela4[[#This Row],[Não liberado para testes]]>0,"Sim","Não") -> Sim | Z15: =IF(Tabela4[[#This Row],[Status]]="Keyuser - Pendente",NETWORKDAYS(Tabela4[[#This Row],[Dt Inicial]],TODAY()),"") | AA15: =AND(Tabela4[[#This Row],[Status]]="Keyuser - Aguardando tarefa precedente",K14="Keyuser - Concluído ") -> FALSE
A16: ="OUT-"&IFERROR(MID(Tabela4[[#This Row],[Cenário]],SEARCH("(",Tabela4[[#This Row],[Cenário]])+1,SEARCH(")",Tabela4[[#This Row],[Cenário]])-SEARCH("(",Tabela4[[#This Row],[Cenário]])-1),"")&"_"&ROW() -> OUT-YRET_16 | B16: Sim | C16: Venda Etanol Hidratado D.E (YRET) | D16: Criar ordem de venda | E16: 1 | F16: Criar ordem de venda | G16: Marcos Nunes | H16: 60668326 | K16: Keyuser - Concluído | L16: 45958 | N16: 45958 | Q16: =COUNTIF(Tabela4[[#All],[Cenário]],Tabela4[[#This Row],[Cenário]]) -> 6 | R16: =COUNTIFS(Tabela4[[#All],[Cenário]],Tabela4[[#This Row],[Cenário]],Tabela4[[#All],[Status]],"Keyuser - Concluído ") -> 5 | S16: =IF(Tabela4[[#This Row],[Tarefas por Cenário]]-Tabela4[[#This Row],[Tarefas Concluídas]]>0,"Não","Sim") -> Não | T16: =COUNTIFS(Tabela4[[#All],[Cenário]],Tabela4[[#This Row],[Cenário]],Tabela4[[#All],[Status]],Tabela4[[#Headers],[Elo - Em correção ]]) -> 0 | U16: =COUNTIFS(Tabela4[[#All],[Cenário]],Tabela4[[#This Row],[Cenário]],Tabela4[[#All],[Status]],Tabela4[[#Headers],[Keyuser - Aguardando tarefa precedente]]) -> 0 | V16: =COUNTIFS(Tabela4[[#All],[Cenário]],Tabela4[[#This Row],[Cenário]],Tabela4[[#All],[Status]],Tabela4[[#Headers],[Não liberado para testes]]) -> 1 | W16: =IF(Tabela4[[#This Row],[Elo - Em correção ]]>0,"Sim","Não") -> Não | X16: =IF(Tabela4[[#This Row],[Keyuser - Aguardando tarefa precedente]]>0,"Sim","Não") -> Não | Y16: =IF(Tabela4[[#This Row],[Não liberado para testes]]>0,"Sim","Não") -> Sim | Z16: =IF(Tabela4[[#This Row],[Status]]="Keyuser - Pendente",NETWORKDAYS(Tabela4[[#This Row],[Dt Inicial]],TODAY()),"") | AA16: =AND(Tabela4[[#This Row],[Status]]="Keyuser - Aguardando tarefa precedente",K15="Keyuser - Concluído ") -> FALSE
A17: ="OUT-"&IFERROR(MID(Tabela4[[#This Row],[Cenário]],SEARCH("(",Tabela4[[#This Row],[Cenário]])+1,SEARCH(")",Tabela4[[#This Row],[Cenário]])-SEARCH("(",Tabela4[[#This Row],[Cenário]])-1),"")&"_"&ROW() -> OUT-YRET_17 | B17: Sim | C17: Venda Etanol Hidratado D.E (YRET) | D17: Realizar validação tributária - Ordem de venda | E17: 2 | F17: Realizar validação tributária - Ordem de venda | G17: Livia Beserra | H17: 60668326 | K17: Keyuser - Concluído | L17: 45958 | N17: 45958 | Q17: =COUNTIF(Tabela4[[#All],[Cenário]],Tabela4[[#This Row],[Cenário]]) -> 6 | R17: =COUNTIFS(Tabela4[[#All],[Cenário]],Tabela4[[#This Row],[Cenário]],Tabela4[[#All],[Status]],"Keyuser - Concluído ") -> 5 | S17: =IF(Tabela4[[#This Row],[Tarefas por Cenário]]-Tabela4[[#This Row],[Tarefas Concluídas]]>0,"Não","Sim") -> Não | T17: =COUNTIFS(Tabela4[[#All],[Cenário]],Tabela4[[#This Row],[Cenário]],Tabela4[[#All],[Status]],Tabela4[[#Headers],[Elo - Em correção ]]) -> 0 | U17: =COUNTIFS(Tabela4[[#All],[Cenário]],Tabela4[[#This Row],[Cenário]],Tabela4[[#All],[Status]],Tabela4[[#Headers],[Keyuser - Aguardando tarefa precedente]]) -> 0 | V17: =COUNTIFS(Tabela4[[#All],[Cenário]],Tabela4[[#This Row],[Cenário]],Tabela4[[#All],[Status]],Tabela4[[#Headers],[Não liberado para testes]]) -> 1 | W17: =IF(Tabela4[[#This Row],[Elo - Em correção ]]>0,"Sim","Não") -> Não | X17: =IF(Tabela4[[#This Row],[Keyuser - Aguardando tarefa precedente]]>0,"Sim","Não") -> Não | Y17: =IF(Tabela4[[#This Row],[Não liberado para testes]]>0,"Sim","Não") -> Sim | Z17: =IF(Tabela4[[#This Row],[Status]]="Keyuser - Pendente",NETWORKDAYS(Tabela4[[#This Row],[Dt Inicial]],TODAY()),"") | AA17: =AND(Tabela4[[#This Row],[Status]]="Keyuser - Aguardando tarefa precedente",K16="Keyuser - Concluído ") -> FALSE
A18: ="OUT-"&IFERROR(MID(Tabela4[[#This Row],[Cenário]],SEARCH("(",Tabela4[[#This Row],[Cenário]])+1,SEARCH(")",Tabela4[[#This Row],[Cenário]])-SEARCH("(",Tabela4[[#This Row],[Cenário]])-1),"")&"_"&ROW() -> OUT-YRET_18 | B18: Sim | C18: Venda Etanol Hidratado D.E (YRET) | D18: Realizar faturamento | E18: 3 | F18: Realizar faturamento | G18: Marcos Nunes | H18: DocNum - 46482290 | K18: Keyuser - Concluído | L18: 45959 | N18: 45959 | O18: Nota nr 149732 | Q18: =COUNTIF(Tabela4[[#All],[Cenário]],Tabela4[[#This Row],[Cenário]]) -> 6 | R18: =COUNTIFS(Tabela4[[#All],[Cenário]],Tabela4[[#This Row],[Cenário]],Tabela4[[#All],[Status]],"Keyuser - Concluído ") -> 5 | S18: =IF(Tabela4[[#This Row],[Tarefas por Cenário]]-Tabela4[[#This Row],[Tarefas Concluídas]]>0,"Não","Sim") -> Não | T18: =COUNTIFS(Tabela4[[#All],[Cenário]],Tabela4[[#This Row],[Cenário]],Tabela4[[#All],[Status]],Tabela4[[#Headers],[Elo - Em correção ]]) -> 0 | U18: =COUNTIFS(Tabela4[[#All],[Cenário]],Tabela4[[#This Row],[Cenário]],Tabela4[[#All],[Status]],Tabela4[[#Headers],[Keyuser - Aguardando tarefa precedente]]) -> 0 | V18: =COUNTIFS(Tabela4[[#All],[Cenário]],Tabela4[[#This Row],[Cenário]],Tabela4[[#All],[Status]],Tabela4[[#Headers],[Não liberado para testes]]) -> 1 | W18: =IF(Tabela4[[#This Row],[Elo - Em correção ]]>0,"Sim","Não") -> Não | X18: =IF(Tabela4[[#This Row],[Keyuser - Aguardando tarefa precedente]]>0,"Sim","Não") -> Não | Y18: =IF(Tabela4[[#This Row],[Não liberado para testes]]>0,"Sim","Não") -> Sim | Z18: =IF(Tabela4[[#This Row],[Status]]="Keyuser - Pendente",NETWORKDAYS(Tabela4[[#This Row],[Dt Inicial]],TODAY()),"") | AA18: =AND(Tabela4[[#This Row],[Status]]="Keyuser - Aguardando tarefa precedente",K17="Keyuser - Concluído ") -> FALSE
A19: ="OUT-"&IFERROR(MID(Tabela4[[#This Row],[Cenário]],SEARCH("(",Tabela4[[#This Row],[Cenário]])+1,SEARCH(")",Tabela4[[#This Row],[Cenário]])-SEARCH("(",Tabela4[[#This Row],[Cenário]])-1),"")&"_"&ROW() -> OUT-YRET_19 | B19: Sim | C19: Venda Etanol Hidratado D.E (YRET) | D19: Realizar validação tributária - SAP, XML e DANFE | E19: 4 | F19: Realizar validação tributária - SAP (xml e DANFE) | G19: Sergio Souza / Giovana Gonçalves | H19: DocNum - 46482290 | K19: Keyuser - Concluído | L19: 45959 | N19: 45959 | Q19: =COUNTIF(Tabela4[[#All],[Cenário]],Tabela4[[#This Row],[Cenário]]) -> 6 | R19: =COUNTIFS(Tabela4[[#All],[Cenário]],Tabela4[[#This Row],[Cenário]],Tabela4[[#All],[Status]],"Keyuser - Concluído ") -> 5 | S19: =IF(Tabela4[[#This Row],[Tarefas por Cenário]]-Tabela4[[#This Row],[Tarefas Concluídas]]>0,"Não","Sim") -> Não | T19: =COUNTIFS(Tabela4[[#All],[Cenário]],Tabela4[[#This Row],[Cenário]],Tabela4[[#All],[Status]],Tabela4[[#Headers],[Elo - Em correção ]]) -> 0 | U19: =COUNTIFS(Tabela4[[#All],[Cenário]],Tabela4[[#This Row],[Cenário]],Tabela4[[#All],[Status]],Tabela4[[#Headers],[Keyuser - Aguardando tarefa precedente]]) -> 0 | V19: =COUNTIFS(Tabela4[[#All],[Cenário]],Tabela4[[#This Row],[Cenário]],Tabela4[[#All],[Status]],Tabela4[[#Headers],[Não liberado para testes]]) -> 1 | W19: =IF(Tabela4[[#This Row],[Elo - Em correção ]]>0,"Sim","Não") -> Não | X19: =IF(Tabela4[[#This Row],[Keyuser - Aguardando tarefa precedente]]>0,"Sim","Não") -> Não | Y19: =IF(Tabela4[[#This Row],[Não liberado para testes]]>0,"Sim","Não") -> Sim | Z19: =IF(Tabela4[[#This Row],[Status]]="Keyuser - Pendente",NETWORKDAYS(Tabela4[[#This Row],[Dt Inicial]],TODAY()),"") | AA19: =AND(Tabela4[[#This Row],[Status]]="Keyuser - Aguardando tarefa precedente",K18="Keyuser - Concluído ") -> FALSE
A20: ="OUT-"&IFERROR(MID(Tabela4[[#This Row],[Cenário]],SEARCH("(",Tabela4[[#This Row],[Cenário]])+1,SEARCH(")",Tabela4[[#This Row],[Cenário]])-SEARCH("(",Tabela4[[#This Row],[Cenário]])-1),"")&"_"&ROW() -> OUT-YRET_20 | B20: Sim | C20: Venda Etanol Hidratado D.E (YRET) | D20: Realizar validação contábil | E20: 5 | F20: Realizar validação contábil | G20: Naiara Toledo | H20: DocNum - 46482290 | K20: Keyuser - Concluído | L20: 45960 | N20: 45960 | Q20: =COUNTIF(Tabela4[[#All],[Cenário]],Tabela4[[#This Row],[Cenário]]) -> 6 | R20: =COUNTIFS(Tabela4[[#All],[Cenário]],Tabela4[[#This Row],[Cenário]],Tabela4[[#All],[Status]],"Keyuser - Concluído ") -> 5 | S20: =IF(Tabela4[[#This Row],[Tarefas por Cenário]]-Tabela4[[#This Row],[Tarefas Concluídas]]>0,"Não","Sim") -> Não | T20: =COUNTIFS(Tabela4[[#All],[Cenário]],Tabela4[[#This Row],[Cenário]],Tabela4[[#All],[Status]],Tabela4[[#Headers],[Elo - Em correção ]]) -> 0 | U20: =COUNTIFS(Tabela4[[#All],[Cenário]],Tabela4[[#This Row],[Cenário]],Tabela4[[#All],[Status]],Tabela4[[#Headers],[Keyuser - Aguardando tarefa precedente]]) -> 0 | V20: =COUNTIFS(Tabela4[[#All],[Cenário]],Tabela4[[#This Row],[Cenário]],Tabela4[[#All],[Status]],Tabela4[[#Headers],[Não liberado para testes]]) -> 1 | W20: =IF(Tabela4[[#This Row],[Elo - Em correção ]]>0,"Sim","Não") -> Não | X20: =IF(Tabela4[[#This Row],[Keyuser - Aguardando tarefa precedente]]>0,"Sim","Não") -> Não | Y20: =IF(Tabela4[[#This Row],[Não liberado para testes]]>0,"Sim","Não") -> Sim | Z20: =IF(Tabela4[[#This Row],[Status]]="Keyuser - Pendente",NETWORKDAYS(Tabela4[[#This Row],[Dt Inicial]],TODAY()),"") | AA20: =AND(Tabela4[[#This Row],[Status]]="Keyuser - Aguardando tarefa precedente",K19="Keyuser - Concluído ") -> FALSE
A21: ="OUT-"&IFERROR(MID(Tabela4[[#This Row],[Cenário]],SEARCH("(",Tabela4[[#This Row],[Cenário]])+1,SEARCH(")",Tabela4[[#This Row],[Cenário]])-SEARCH("(",Tabela4[[#This Row],[Cenário]])-1),"")&"_"&ROW() -> OUT-YRET_21 | B21: Não | C21: Venda Etanol Hidratado D.E (YRET) | D21: Realizar validação Obrigações Acessórias - TaxOne | E21: 6 | F21: Realizar validação Obrigações Acessórias - TaxOne | G21: Sergio Souza / Giovana Gonçalves | K21: Não liberado para testes | Q21: =COUNTIF(Tabela4[[#All],[Cenário]],Tabela4[[#This Row],[Cenário]]) -> 6 | R21: =COUNTIFS(Tabela4[[#All],[Cenário]],Tabela4[[#This Row],[Cenário]],Tabela4[[#All],[Status]],"Keyuser - Concluído ") -> 5 | S21: =IF(Tabela4[[#This Row],[Tarefas por Cenário]]-Tabela4[[#This Row],[Tarefas Concluídas]]>0,"Não","Sim") -> Não | T21: =COUNTIFS(Tabela4[[#All],[Cenário]],Tabela4[[#This Row],[Cenário]],Tabela4[[#All],[Status]],Tabela4[[#Headers],[Elo - Em correção ]]) -> 0 | U21: =COUNTIFS(Tabela4[[#All],[Cenário]],Tabela4[[#This Row],[Cenário]],Tabela4[[#All],[Status]],Tabela4[[#Headers],[Keyuser - Aguardando tarefa precedente]]) -> 0 | V21: =COUNTIFS(Tabela4[[#All],[Cenário]],Tabela4[[#This Row],[Cenário]],Tabela4[[#All],[Status]],Tabela4[[#Headers],[Não liberado para testes]]) -> 1 | W21: =IF(Tabela4[[#This Row],[Elo - Em correção ]]>0,"Sim","Não") -> Não | X21: =IF(Tabela4[[#This Row],[Keyuser - Aguardando tarefa precedente]]>0,"Sim","Não") -> Não | Y21: =IF(Tabela4[[#This Row],[Não liberado para testes]]>0,"Sim","Não") -> Sim | Z21: =IF(Tabela4[[#This Row],[Status]]="Keyuser - Pendente",NETWORKDAYS(Tabela4[[#This Row],[Dt Inicial]],TODAY()),"") | AA21: =AND(Tabela4[[#This Row],[Status]]="Keyuser - Aguardando tarefa precedente",K20="Keyuser - Concluído ") -> FALSE
A22: ="OUT-"&IFERROR(MID(Tabela4[[#This Row],[Cenário]],SEARCH("(",Tabela4[[#This Row],[Cenário]])+1,SEARCH(")",Tabela4[[#This Row],[Cenário]])-SEARCH("(",Tabela4[[#This Row],[Cenário]])-1),"")&"_"&ROW() -> OUT-Y002_22 | B22: Sim | C22: Venda Etanol Hidratado F.E (Y002) | D22: Criar ordem de venda | E22: 1 | F22: Criar ordem de venda | G22: Vania Esteves | H22: 15603629 | I22: BEP: 15608806 | J22: OK | K22: Keyuser - Concluído | L22: 45951 | N22: 45951 | Q22: =COUNTIF(Tabela4[[#All],[Cenário]],Tabela4[[#This Row],[Cenário]]) -> 8 | R22: =COUNTIFS(Tabela4[[#All],[Cenário]],Tabela4[[#This Row],[Cenário]],Tabela4[[#All],[Status]],"Keyuser - Concluído ") -> 7 | S22: =IF(Tabela4[[#This Row],[Tarefas por Cenário]]-Tabela4[[#This Row],[Tarefas Concluídas]]>0,"Não","Sim") -> Não | T22: =COUNTIFS(Tabela4[[#All],[Cenário]],Tabela4[[#This Row],[Cenário]],Tabela4[[#All],[Status]],Tabela4[[#Headers],[Elo - Em correção ]]) -> 0 | U22: =COUNTIFS(Tabela4[[#All],[Cenário]],Tabela4[[#This Row],[Cenário]],Tabela4[[#All],[Status]],Tabela4[[#Headers],[Keyuser - Aguardando tarefa precedente]]) -> 0 | V22: =COUNTIFS(Tabela4[[#All],[Cenário]],Tabela4[[#This Row],[Cenário]],Tabela4[[#All],[Status]],Tabela4[[#Headers],[Não liberado para testes]]) -> 1 | W22: =IF(Tabela4[[#This Row],[Elo - Em correção ]]>0,"Sim","Não") -> Não | X22: =IF(Tabela4[[#This Row],[Keyuser - Aguardando tarefa precedente]]>0,"Sim","Não") -> Não | Y22: =IF(Tabela4[[#This Row],[Não liberado para testes]]>0,"Sim","Não") -> Sim | Z22: =IF(Tabela4[[#This Row],[Status]]="Keyuser - Pendente",NETWORKDAYS(Tabela4[[#This Row],[Dt Inicial]],TODAY()),"") | AA22: =AND(Tabela4[[#This Row],[Status]]="Keyuser - Aguardando tarefa precedente",K21="Keyuser - Concluído ") -> FALSE
